[0m16:41:04.670006 [debug] [MainThread]: Got an exception trying to initialize tracking


============================== 16:41:04.788889 | cd42c1a5-28d5-4db6-8d26-c0c210a2948f ==============================
[0m16:41:04.788889 [info ] [MainThread]: Running with dbt=1.10.11
[0m16:41:04.790172 [debug] [MainThread]: running dbt with arguments {'partial_parse': 'True', 'warn_error_options': 'WarnErrorOptionsV2(error=[], warn=[], silence=[])', 'send_anonymous_usage_stats': 'True', 'use_colors': 'True', 'cache_selected_only': 'False', 'target_path': 'None', 'version_check': 'True', 'invocation_command': 'dbt init', 'log_format': 'default', 'warn_error': 'None', 'introspect': 'True', 'debug': 'False', 'printer_width': '80', 'fail_fast': 'False', 'no_print': 'None', 'empty': 'None', 'quiet': 'False', 'log_cache_events': 'False', 'use_experimental_parser': 'False', 'log_path': 'logs', 'indirect_selection': 'eager', 'profiles_dir': 'C:\\Users\\Administrator\\.dbt', 'static_parser': 'True', 'write_json': 'True'}
[0m16:41:43.772124 [debug] [MainThread]: Starter project path: C:\Users\Administrator\LocalMachine\Lib\site-packages\dbt\include\starter_project
[0m16:41:43.816878 [info ] [MainThread]: 
Your new dbt project "taxi_rides_ny" was created!

For more information on how to configure the profiles.yml file,
please consult the dbt documentation here:

  https://docs.getdbt.com/docs/configure-your-profile

One more thing:

Need help? Don't hesitate to reach out to us via GitHub issues or on Slack:

  https://community.getdbt.com/

Happy modeling!

[0m16:41:43.818556 [info ] [MainThread]: Setting up your profile.
[0m16:41:50.365234 [debug] [MainThread]: Command `dbt init` succeeded at 16:41:50.364927 after 45.78 seconds
[0m16:41:50.365948 [debug] [MainThread]: Flushing usage events
[0m18:45:49.671794 [debug] [MainThread]: Sending event: {'category': 'dbt', 'action': 'invocation', 'label': 'start', 'context': [<snowplow_tracker.self_describing_json.SelfDescribingJson object at 0x0000028E812C6F90>, <snowplow_tracker.self_describing_json.SelfDescribingJson object at 0x0000028E812C7290>, <snowplow_tracker.self_describing_json.SelfDescribingJson object at 0x0000028E811DA590>]}


============================== 18:45:49.680232 | ae8b7001-f76d-45eb-8cf2-adb327bbad53 ==============================
[0m18:45:49.680232 [info ] [MainThread]: Running with dbt=1.10.13
[0m18:45:49.680232 [debug] [MainThread]: running dbt with arguments {'partial_parse': 'True', 'static_parser': 'True', 'send_anonymous_usage_stats': 'True', 'warn_error': 'None', 'cache_selected_only': 'False', 'target_path': 'None', 'version_check': 'True', 'invocation_command': 'dbt run-operation generate_model_yaml --args {"model_names": ["stg_green_tripdata"]}', 'log_format': 'default', 'use_colors': 'True', 'introspect': 'True', 'debug': 'False', 'log_cache_events': 'False', 'fail_fast': 'False', 'no_print': 'None', 'empty': 'None', 'quiet': 'False', 'use_experimental_parser': 'False', 'printer_width': '80', 'indirect_selection': 'eager', 'log_path': 'logs', 'profiles_dir': 'C:\\Users\\Administrator\\.dbt', 'warn_error_options': 'WarnErrorOptionsV2(error=[], warn=[], silence=[])', 'write_json': 'True'}
[0m18:45:49.682252 [error] [MainThread]: Encountered an error:
Runtime Error
  No dbt_project.yml found at expected path C:\Users\Administrator\Python-Virtual-Environments\DE-Zoomcamp-Demo\dbt_project.yml
  Verify that each entry within packages.yml (and their transitive dependencies) contains a file named dbt_project.yml
  
[0m18:45:49.684270 [debug] [MainThread]: Command `dbt run-operation` failed at 18:45:49.684270 after 0.10 seconds
[0m18:45:49.684270 [debug] [MainThread]: Sending event: {'category': 'dbt', 'action': 'invocation', 'label': 'end', 'context': [<snowplow_tracker.self_describing_json.SelfDescribingJson object at 0x0000028E8133E490>, <snowplow_tracker.self_describing_json.SelfDescribingJson object at 0x0000028E8133D9D0>, <snowplow_tracker.self_describing_json.SelfDescribingJson object at 0x0000028E812B4B10>]}
[0m18:45:49.684270 [debug] [MainThread]: Flushing usage events
[0m18:45:51.763045 [debug] [MainThread]: An error was encountered while trying to flush usage events
